"""
The purpose of this test suite is to ensure that Weave can handle various types of errors that can occur during tracing.

We should never be breaking the user's program with an error.
"""

import importlib
from typing import Callable, Iterator

# TODO: Test code capture resilience
# TODO: Test postprocess input/output resilience
import pytest

import weave
from weave.trace import call_context
from weave.trace.context import raise_on_captured_errors
from weave.trace.op_extensions.accumulator import add_accumulator
from weave.trace.patcher import MultiPatcher, SymbolPatcher
from weave.trace_server import trace_server_interface as tsi


class TestException(Exception):
    pass


def assert_no_current_call():
    assert call_context.get_current_call() is None


def test_resilience_to_user_code_errors(client):
    def do_test():
        @weave.op
        def throws():
            raise TestException("This is a test exception")

        throws()

    # The user's exception should be raised - even if we're capturing errors
    with pytest.raises(TestException):
        do_test()

    # The user's exception should be raised - even if we're not capturing errors
    with raise_on_captured_errors(False):
        with pytest.raises(TestException):
            do_test()

    assert_no_current_call()


class ThrowingServer(tsi.TraceServerInterface):
    # Call API
    def call_start(self, req: tsi.CallStartReq) -> tsi.CallStartRes:
        raise TestException("FAILURE!")

    def call_end(self, req: tsi.CallEndReq) -> tsi.CallEndRes:
        raise TestException("FAILURE!")

    def call_read(self, req: tsi.CallReadReq) -> tsi.CallReadRes:
        raise TestException("FAILURE!")

    def calls_query(self, req: tsi.CallsQueryReq) -> tsi.CallsQueryRes:
        raise TestException("FAILURE!")

    def calls_query_stream(self, req: tsi.CallsQueryReq) -> Iterator[tsi.CallSchema]:
        raise TestException("FAILURE!")

    def calls_delete(self, req: tsi.CallsDeleteReq) -> tsi.CallsDeleteRes:
        raise TestException("FAILURE!")

    def calls_query_stats(self, req: tsi.CallsQueryStatsReq) -> tsi.CallsQueryStatsRes:
        raise TestException("FAILURE!")

    def call_update(self, req: tsi.CallUpdateReq) -> tsi.CallUpdateRes:
        raise TestException("FAILURE!")

    # Op API
    def op_create(self, req: tsi.OpCreateReq) -> tsi.OpCreateRes:
        raise TestException("FAILURE!")

    def op_read(self, req: tsi.OpReadReq) -> tsi.OpReadRes:
        raise TestException("FAILURE!")

    def ops_query(self, req: tsi.OpQueryReq) -> tsi.OpQueryRes:
        raise TestException("FAILURE!")

    # Cost API
    def cost_create(self, req: tsi.CostCreateReq) -> tsi.CostCreateRes:
        raise TestException("FAILURE!")

    def cost_query(self, req: tsi.CostQueryReq) -> tsi.CostQueryRes:
        raise TestException("FAILURE!")

    def cost_purge(self, req: tsi.CostPurgeReq) -> tsi.CostPurgeRes:
        raise TestException("FAILURE!")

    # Obj API
    def obj_create(self, req: tsi.ObjCreateReq) -> tsi.ObjCreateRes:
        raise TestException("FAILURE!")

    def obj_read(self, req: tsi.ObjReadReq) -> tsi.ObjReadRes:
        raise TestException("FAILURE!")

    def objs_query(self, req: tsi.ObjQueryReq) -> tsi.ObjQueryRes:
        raise TestException("FAILURE!")

    def table_create(self, req: tsi.TableCreateReq) -> tsi.TableCreateRes:
        raise TestException("FAILURE!")

    def table_update(self, req: tsi.TableUpdateReq) -> tsi.TableUpdateRes:
        raise TestException("FAILURE!")

    def table_query(self, req: tsi.TableQueryReq) -> tsi.TableQueryRes:
        raise TestException("FAILURE!")

    def refs_read_batch(self, req: tsi.RefsReadBatchReq) -> tsi.RefsReadBatchRes:
        raise TestException("FAILURE!")

    def file_create(self, req: tsi.FileCreateReq) -> tsi.FileCreateRes:
        raise TestException("FAILURE!")

    def file_content_read(self, req: tsi.FileContentReadReq) -> tsi.FileContentReadRes:
        raise TestException("FAILURE!")

    def feedback_create(self, req: tsi.FeedbackCreateReq) -> tsi.FeedbackCreateRes:
        raise TestException("FAILURE!")

    def feedback_query(self, req: tsi.FeedbackQueryReq) -> tsi.FeedbackQueryRes:
        raise TestException("FAILURE!")

    def feedback_purge(self, req: tsi.FeedbackPurgeReq) -> tsi.FeedbackPurgeRes:
        raise TestException("FAILURE!")


@pytest.mark.skip(
    "TODO: Unskip after Tim's backgrounding PR goes in (add one for the entire eval workflow)"
)
def test_resilience_to_server_errors(client):
    client.server = ThrowingServer()

    def do_test():
        @weave.op
        def simple_op():
            return "hello"

        return simple_op()

    # The user's exception should be raised - even if we're capturing errors
    with pytest.raises(TestException):
        do_test()

    # We should gracefully handle the error and return a value
    with raise_on_captured_errors(False):
        res = do_test()
        assert res == "hello"

    assert_no_current_call()


def test_resilience_to_patcher_errors(client):
    class Module:
        def method(self):
            return 0

    def custom_patcher(m: Callable):
        raise TestException("FAILURE!")

    def do_test():
        test_patcher = MultiPatcher(
            [
                SymbolPatcher(
                    lambda: Module,
                    "method",
                    custom_patcher,
                )
            ]
        )

        test_patcher.attempt_patch()

        return Module().method()

    res = do_test()
    assert res == 0

    assert_no_current_call()


def test_resilience_to_output_handler_errors(client):
    def do_test():
        @weave.op
        def simple_op():
            return "hello"

        def on_output_handler(*args, **kwargs):
            raise TestException("FAILURE!")

        simple_op._set_on_output_handler(on_output_handler)

        return simple_op()

    # The user's exception should be raised - even if we're capturing errors
    with pytest.raises(TestException):
        do_test()

    # We should gracefully handle the error and return a value
    with raise_on_captured_errors(False):
        res = do_test()
        assert res == "hello"

    assert_no_current_call()


@pytest.mark.asyncio
async def test_resilience_to_output_handler_errors_async(client):
    async def do_test():
        @weave.op
        async def simple_op():
            return "hello"

        def on_output_handler(*args, **kwargs):
            raise TestException("FAILURE!")

        simple_op._set_on_output_handler(on_output_handler)

        return await simple_op()

    # The user's exception should be raised - even if we're capturing errors
    with pytest.raises(TestException):
        await do_test()

    # We should gracefully handle the error and return a value
    with raise_on_captured_errors(False):
        res = await do_test()
        assert res == "hello"

    assert_no_current_call()


def test_resilience_to_accumulator_make_accumulator_errors(client):
    def do_test():
        @weave.op
        def simple_op():
            yield from [1, 2, 3]

        def make_accumulator(*args, **kwargs):
            raise TestException("FAILURE!")

        add_accumulator(simple_op, make_accumulator=make_accumulator)

        return simple_op()

    # The user's exception should be raised - even if we're capturing errors
    with pytest.raises(TestException):
        do_test()

    # We should gracefully handle the error and return a value
    with raise_on_captured_errors(False):
        res = do_test()
        assert list(res) == [1, 2, 3]

    assert_no_current_call()


@pytest.mark.asyncio
async def test_resilience_to_accumulator_make_accumulator_errors_async(client):
    async def do_test():
        @weave.op
        async def simple_op():
            yield 1
            yield 2
            yield 3

        def make_accumulator(*args, **kwargs):
            raise TestException("FAILURE!")

        add_accumulator(simple_op, make_accumulator=make_accumulator)

        return simple_op()

    # The user's exception should be raised - even if we're capturing errors
    with pytest.raises(TestException):
        await do_test()

    # We should gracefully handle the error and return a value
    with raise_on_captured_errors(False):
        res = await do_test()
        assert [item async for item in res] == [1, 2, 3]

    assert_no_current_call()


def test_resilience_to_accumulator_accumulation_errors(client):
    def do_test():
        @weave.op
        def simple_op():
            yield from [1, 2, 3]

        def make_accumulator(*args, **kwargs):
            def accumulate(*args, **kwargs):
                raise TestException("FAILURE!")

            return accumulate

        add_accumulator(simple_op, make_accumulator=make_accumulator)

        return simple_op()

    # The user's exception should be raised - even if we're capturing errors
    with pytest.raises(TestException):
        list(do_test())

    # We should gracefully handle the error and return a value
    with raise_on_captured_errors(False):
        res = do_test()
        assert list(res) == [1, 2, 3]

    assert_no_current_call()


@pytest.mark.asyncio
async def test_resilience_to_accumulator_accumulation_errors_async(client):
    async def do_test():
        @weave.op
        async def simple_op():
            yield 1
            yield 2
            yield 3

        def make_accumulator(*args, **kwargs):
            def accumulate(*args, **kwargs):
                raise TestException("FAILURE!")

            return accumulate

        add_accumulator(simple_op, make_accumulator=make_accumulator)

        return simple_op()

    # The user's exception should be raised - even if we're capturing errors
    with pytest.raises(TestException):
        res = await do_test()
        l = [item async for item in res]

    # We should gracefully handle the error and return a value
    with raise_on_captured_errors(False):
        res = await do_test()
        assert [item async for item in res] == [1, 2, 3]

    assert_no_current_call()


def test_resilience_to_accumulator_should_accumulate_errors(client):
    def do_test():
        @weave.op
        def simple_op():
            yield from [1, 2, 3]

        def make_accumulator(*args, **kwargs):
            def accumulate(*args, **kwargs):
                return {}

            return accumulate

        def should_accumulate(*args, **kwargs):
            raise TestException("FAILURE!")

        add_accumulator(
            simple_op,
            make_accumulator=make_accumulator,
            should_accumulate=should_accumulate,
        )

        return simple_op()

    # The user's exception should be raised - even if we're capturing errors
    with pytest.raises(TestException):
        list(do_test())

    # We should gracefully handle the error and return a value
    with raise_on_captured_errors(False):
        res = do_test()
        assert list(res) == [1, 2, 3]

    assert_no_current_call()


@pytest.mark.asyncio
async def test_resilience_to_accumulator_should_accumulate_errors_async(client):
    async def do_test():
        @weave.op
        async def simple_op():
            yield 1
            yield 2
            yield 3

        def make_accumulator(*args, **kwargs):
            async def accumulate(*args, **kwargs):
                return {}

            return accumulate

        def should_accumulate(*args, **kwargs):
            raise TestException("FAILURE!")

        add_accumulator(
            simple_op,
            make_accumulator=make_accumulator,
            should_accumulate=should_accumulate,
        )

        return simple_op()

    # The user's exception should be raised - even if we're capturing errors
    with pytest.raises(TestException):
        await do_test()

    # We should gracefully handle the error and return a value
    with raise_on_captured_errors(False):
        res = await do_test()
        assert [item async for item in res] == [1, 2, 3]

    assert_no_current_call()


def test_resilience_to_accumulator_on_finish_post_processor_errors(client):
    def do_test():
        @weave.op
        def simple_op():
            yield from [1, 2, 3]

        def make_accumulator(*args, **kwargs):
            def accumulate(*args, **kwargs):
                return {}

            return accumulate

        def on_finish_post_processor(*args, **kwargs):
            raise TestException("FAILURE!")

        add_accumulator(
            simple_op,
            make_accumulator=make_accumulator,
            on_finish_post_processor=on_finish_post_processor,
        )

        return simple_op()

    # The user's exception should be raised - even if we're capturing errors
    with pytest.raises(TestException):
        list(do_test())

    # We should gracefully handle the error and return a value
    with raise_on_captured_errors(False):
        res = do_test()
        assert list(res) == [1, 2, 3]

    assert_no_current_call()


@pytest.mark.asyncio
async def test_resilience_to_accumulator_on_finish_post_processor_errors_async(client):
    async def do_test():
        @weave.op
        async def simple_op():
            yield 1
            yield 2
            yield 3

        def make_accumulator(*args, **kwargs):
            async def accumulate(*args, **kwargs):
                return {}

            return accumulate

        def on_finish_post_processor(*args, **kwargs):
            raise TestException("FAILURE!")

        add_accumulator(
            simple_op,
            make_accumulator=make_accumulator,
            on_finish_post_processor=on_finish_post_processor,
        )

        return simple_op()

    # The user's exception should be raised - even if we're capturing errors
    with pytest.raises(TestException):
        res = await do_test()
        l = [item async for item in res]

    # We should gracefully handle the error and return a value
    with raise_on_captured_errors(False):
        res = await do_test()
        assert [item async for item in res] == [1, 2, 3]

    assert_no_current_call()


def test_resilience_to_accumulator_internal_errors(client):
    def do_test():
        @weave.op
        def simple_op():
            yield 1
            raise TestException("FAILURE!")

        def make_accumulator(*args, **kwargs):
            def accumulate(*args, **kwargs):
                return {}

            return accumulate

        add_accumulator(simple_op, make_accumulator=make_accumulator)

        return simple_op()

    # The user's exception should be raised - even if we're capturing errors
    with pytest.raises(TestException):
        list(do_test())

    # User errors should still be raised
    with raise_on_captured_errors(False):
        with pytest.raises(TestException):
            list(do_test())

    assert_no_current_call()


@pytest.mark.asyncio
async def test_resilience_to_accumulator_internal_errors_async(client):
    async def do_test():
        @weave.op
        async def simple_op():
            yield 1
            raise TestException("FAILURE!")

        def make_accumulator(*args, **kwargs):
            async def accumulate(*args, **kwargs):
                return {}

            return accumulate

        add_accumulator(simple_op, make_accumulator=make_accumulator)

        return simple_op()

    # The user's exception should be raised - even if we're capturing errors
    with pytest.raises(TestException):
        res = await do_test()
        l = [item async for item in res]

    # User errors should still be raised
    with raise_on_captured_errors(False):
        with pytest.raises(TestException):
            res = await do_test()
            l = [item async for item in res]

    assert_no_current_call()
